<?xml version="1.0"?>
<robot name="myfirst">

   <material name="blue">
     <color rgba="0 0 0.8 1"/>
   </material>
 
   <material name="white">
     <color rgba="1 1 1 1"/>
   </material>

   <material name="black">
     <color rgba="0 0 0 1"/>
   </material>

   <material name="red">
     <color rgba="0.8 0 0 1"/>
   </material>

   <link name="zero_point"/>
     
   <link name="base_link">
     <visual>
       <geometry>
         <cylinder length="1.0" radius="0.2"/>
       </geometry>
       <origin rpy="0 -1.5708 0" xyz="0.5 0 0"/>
       <material name="blue"/>
     </visual>
   </link>
   
   <joint name="zero_point_to_base_link" type="fixed">
     <parent link="zero_point"/>
     <child link="base_link"/>
     <origin xyz="0 0 1" rpy="0 1.5708 0"/>
   </joint>

   <link name="arm3">
     <visual>
       <geometry>
         <box size="0.1 0.1 1.1"/>
       </geometry>
       <origin rpy="0 0 0" xyz="0 0 -0.5"/>
       <material name="white"/>
     </visual>
   </link>
  
    <joint name="base_to_arm3" type="prismatic">
      <parent link="base_link"/>
      <child link="arm3"/>
      <origin xyz="0 0 0.5" rpy="0 0 0"/>
      <axis xyz="0 0 1"/>
      <limit upper="0.5" lower="-0.5" effort="0" velocity="0.2"/>
    </joint>
    
    <link name="arm2">
      <visual>
        <geometry>
          <box size="0.1 0.1 1.1"/>
        </geometry>
        <origin rpy="0 0 0" xyz="0 0 0.5"/>
        <material name="white"/>
      </visual>
    </link>

    <joint name="arm3_to_arm2" type="prismatic">
      <parent link="arm3"/>
      <child link="arm2"/>
      <origin xyz="0 0.5 0" rpy="1.5708 -1.5708 0"/>
      <axis xyz="0 0 1"/>
      <limit upper="0.5" lower="-0.5" effort="0" velocity="0.2"/>
    </joint>

    <link name="arm1">
      <visual>
        <geometry>
          <box size="0.1 0.1 1.1"/>
        </geometry>
        <origin rpy="0 0 0" xyz="0 0 0.5"/>
        <material name="white"/>
      </visual>
    </link>

    <joint name="arm2_to_arm1" type="prismatic">
      <parent link="arm2"/>
      <child link="arm1"/>
      <origin xyz="0 0.5 0" rpy="1.5708 -1.5708 0"/>
      <axis xyz="0 0 1"/>
      <limit upper="0.5" lower="-0.5" effort="0" velocity="0.2"/>
    </joint>

</robot>
									
